<robot name="Basic_Robot">
  <material name="silver">
    <color rgba="0.700 0.700 0.700 1.000" />
  </material>
  <transmission name="Rev1_tran">
    <type>transmission_interface/SimpleTransmission</type>
    <joint name="Rev1">
      <hardwareInterface>hardware_interface/EffortJointInterface</hardwareInterface>
    </joint>
    <actuator name="Rev1_actr">
      <hardwareInterface>hardware_interface/EffortJointInterface</hardwareInterface>
      <mechanicalReduction>1</mechanicalReduction>
    </actuator>
  </transmission>
  <transmission name="Rev2_tran">
    <type>transmission_interface/SimpleTransmission</type>
    <joint name="Rev2">
      <hardwareInterface>hardware_interface/EffortJointInterface</hardwareInterface>
    </joint>
    <actuator name="Rev2_actr">
      <hardwareInterface>hardware_interface/EffortJointInterface</hardwareInterface>
      <mechanicalReduction>1</mechanicalReduction>
    </actuator>
  </transmission>
  <gazebo>
    <plugin filename="libgazebo_ros_control.so" name="control" />
  </gazebo>
  <gazebo reference="base_link">
    <material>Gazebo/Silver</material>
    <mu1>0.2</mu1>
    <mu2>0.2</mu2>
    <selfCollide>true</selfCollide>
    <gravity>true</gravity>
  </gazebo>
  <gazebo reference="right_wheel_1">
    <material>Gazebo/Silver</material>
    <mu1>0.2</mu1>
    <mu2>0.2</mu2>
    <selfCollide>true</selfCollide>
  </gazebo>
  <gazebo reference="left_wheel_1">
    <material>Gazebo/Silver</material>
    <mu1>0.2</mu1>
    <mu2>0.2</mu2>
    <selfCollide>true</selfCollide>
  </gazebo>
  <link name="base_link">
    <inertial>
      <origin rpy="0 0 0" xyz="0.047517484701943946 0.004858805619815502 -0.0300059480762529" />
      <mass value="0.4424914005445932" />
      <inertia ixx="0.000128" ixy="2e-06" ixz="-0.0" iyy="0.00046" iyz="0.0" izz="0.000341" />
    </inertial>
    <visual>
      <origin rpy="0 0 0" xyz="0 0 0" />
      <geometry>
        <cylinder length="0.09995600128173829" radius="0.06" /></geometry>
      <material name="silver" />
    </visual>
    <collision>
      <origin rpy="0 0 0" xyz="0 0 0" />
      <geometry>
        <cylinder length="0.09995600128173829" radius="0.06" /></geometry>
    </collision>
  </link>
  <link name="right_wheel_1">
    <inertial>
      <origin rpy="0 0 0" xyz="0.005000000000000007 4.336808689942018e-18 -0.001427613941018771" />
      <mass value="0.015522874373267303" />
      <inertia ixx="1e-06" ixy="0.0" ixz="-0.0" iyy="1e-06" iyz="0.0" izz="2e-06" />
    </inertial>
    <visual>
      <origin rpy="0 0 0" xyz="-0.0 -0.005 0.06" />
      <geometry>
        <cylinder length="0.029991756439208987" radius="0.02998351287841797" /></geometry>
      <material name="silver" />
    </visual>
    <collision>
      <origin rpy="0 0 0" xyz="-0.0 -0.005 0.06" />
      <geometry>
        <cylinder length="0.029991756439208987" radius="0.02998351287841797" /></geometry>
    </collision>
  </link>
  <link name="left_wheel_1">
    <inertial>
      <origin rpy="0 0 0" xyz="0.004999999999999999 0.0 0.0014276139410187671" />
      <mass value="0.015522874373267314" />
      <inertia ixx="1e-06" ixy="-0.0" ixz="-0.0" iyy="1e-06" iyz="0.0" izz="2e-06" />
    </inertial>
    <visual>
      <origin rpy="0 0 0" xyz="-0.0 -0.005 -0.0" />
      <geometry>
        <cylinder length="0.029991756439208987" radius="0.02998351287841797" /></geometry>
      <material name="silver" />
    </visual>
    <collision>
      <origin rpy="0 0 0" xyz="-0.0 -0.005 -0.0" />
      <geometry>
        <cylinder length="0.029991756439208987" radius="0.02998351287841797" /></geometry>
    </collision>
  </link>
  <joint name="Rev1" type="continuous">
    <origin rpy="0 0 0" xyz="0.0 0.005 -0.06" />
    <parent link="base_link" />
    <child link="right_wheel_1" />
    <axis xyz="0.0 0.0 -1.0" />
  </joint>
  <joint name="Rev2" type="continuous">
    <origin rpy="0 0 0" xyz="0.0 0.005 0.0" />
    <parent link="base_link" />
    <child link="left_wheel_1" />
    <axis xyz="0.0 0.0 1.0" />
  </joint>
</robot>